Workbook
Name Applied: 'Helper(IMPORTANT!)'!$D$4:$D$11
Name Core: 'Helper(IMPORTANT!)'!$C$4:$C$22
Name ngoyab: 'SF10 FRONT'!$A$6:$BO$20
Name Other_Subjects: 'Helper(IMPORTANT!)'!$F$4:$F$6
Name Specialized: 'Helper(IMPORTANT!)'!$E$4:$E$12
Name STRAND: #REF!

Sheet SF10 FRONT
P1: REPUBLIC OF THE PHILIPPINES | BH1: SF10-SHS
P2: DEPARTMENT OF EDUCATION
P3: SENIOR HIGH SCHOOL STUDENT PERMANENT RECORD
A6: LEARNER'S INFORMATION
A8: LAST NAME: | F8: =IFERROR(VLOOKUP($C$9,#REF!,2,FALSE),"") | T8: FIRST NAME: | Y8: =IFERROR(VLOOKUP($C$9,#REF!,3,FALSE),"") | AS8: MIDDLE NAME: | AZ8: =IF(IFERROR(VLOOKUP($C$9,#REF!,4,FALSE),"")="","",IFERROR(VLOOKUP($C$9,#REF!,4,FALSE),""))
A9: LRN: | C9: =IF(BP8="","",VLOOKUP(BP8,#REF!,3,FALSE)) | R9: Date of Birth (MM/DD/YYYY): | AA9: =IFERROR(VLOOKUP($C$9,#REF!,5,FALSE),"") | AL9: Sex: | AN9: =IFERROR(VLOOKUP($C$9,#REF!,7,FALSE),"") | AS9: Date of SHS Admission (MM/DD/YYYY): | BH9: =IFERROR(VLOOKUP($C$9,#REF!,8,FALSE),"")
A11: ELIGIBILITY FOR SHS ENROLMENT
A13: =IF(N13="","","⁄") | B13: High School Completer* | K13: Gen. Ave: | N13: =IFERROR(IF(VLOOKUP($C$9,#REF!,21,FALSE)="","",VLOOKUP($C$9,#REF!,21,FALSE)),"") | S13: =IF(AH13="","","⁄") | T13: Junior High School Completer | AD13: Gen. Ave: | AH13: =IFERROR(IF(VLOOKUP($C$9,#REF!,22,FALSE)="","",VLOOKUP($C$9,#REF!,22,FALSE)),"")
A14: Date of Graduation/Completion (MM/DD/YYYY): | P14: =IFERROR(IF(VLOOKUP($C$9,#REF!,23,FALSE)="","",VLOOKUP($C$9,#REF!,23,FALSE)),"") | U14: Name of School: | Z14: =IFERROR(IF(VLOOKUP($C$9,#REF!,24,FALSE)="","",VLOOKUP($C$9,#REF!,24,FALSE)),"") | AQ14: School Address: | AW14: =IFERROR(IF(VLOOKUP($C$9,#REF!,25,FALSE)="","",VLOOKUP($C$9,#REF!,25,FALSE)),"")
A16: =IF(K16="","","⁄") | B16: PEPT Passer** | H16: Rating: | K16: =IFERROR(IF(VLOOKUP($C$9,#REF!,26,FALSE)="","",VLOOKUP($C$9,#REF!,26,FALSE)),"") | S16: =IF(AN17="","","⁄") | T16: ALS A&E Passer*** | Z16: Rating: | AC16: =IFERROR(IF(VLOOKUP($C$9,#REF!,28,FALSE)="","",VLOOKUP($C$9,#REF!,28,FALSE)),"") | AI16: Others (Pls. Specify):
A17: Date of Examination/Assessment (MM/DD/YYYY): | P17: =IFERROR(IF(VLOOKUP($C$9,#REF!,27,FALSE)="","",VLOOKUP($C$9,#REF!,27,FALSE)),"") | W17: Name and Address of Community Learning Center: | AN17: =IFERROR(IF(VLOOKUP($C$9,#REF!,29,FALSE)="","",VLOOKUP($C$9,#REF!,29,FALSE)),"")
A18: *High School Completers are students who graduated from secondary school under the old curriculum | AG18: ***ALS A&E - Alternative Learning System Accreditation and Equivalency Test for JHS
A19: **PEPT - Philippine Educational Placement Test for JHS
A21: SCHOLASTIC RECORD
A23: SCHOOL: | E23: =IFERROR(IF(VLOOKUP($C$9,#REF!,30,FALSE)="","",VLOOKUP($C$9,#REF!,30,FALSE)),"") | AB23: SCHOOL ID: | AF23: =IFERROR(IF(VLOOKUP($C$9,#REF!,31,FALSE)="","",VLOOKUP($C$9,#REF!,31,FALSE)),"") | AM23: GRADE LEVEL: | AS23: =IFERROR(IF(VLOOKUP($C$9,#REF!,32,FALSE)="","",VLOOKUP($C$9,#REF!,32,FALSE)),"") | AY23: SY: | BA23: =IFERROR(IF(VLOOKUP($C$9,#REF!,33,FALSE)="","",VLOOKUP($C$9,#REF!,33,FALSE)),"") | BH23: SEM: | BK23: =IFERROR(IF(VLOOKUP($C$9,#REF!,36,FALSE)="","",VLOOKUP($C$9,#REF!,36,FALSE)),"")
A25: TRACK/STRAND: | G25: =IFERROR(IF(VLOOKUP($C$9,#REF!,34,FALSE)="","",VLOOKUP($C$9,#REF!,34,FALSE)),"") | AN25: SECTION: | AS25: =IFERROR(IF(VLOOKUP($C$9,#REF!,35,FALSE)="","",VLOOKUP($C$9,#REF!,35,FALSE)),"")
A27: Indicate if Subject is CORE, APPLIED, or SPECIALIZED | I27: SUBJECTS | AT27: Quarter | BD27: SEM FINAL GRADE | BI27: ACTION TAKEN
AT29: =IF(BK23="","",IF(BK23="1ST","1ST",IF(BK23="2ND","3RD"))) | AY29: =IF(BK23="","",IF(BK23="1ST","2ND",IF(BK23="2ND","4TH")))
A31: =IFERROR(VLOOKUP(I31,#REF!,2,FALSE),"") | I31: =IFERROR(IF(VLOOKUP($C$9,#REF!,37,FALSE)="","",VLOOKUP($C$9,#REF!,37,FALSE)),"") | AT31: =IFERROR(IF(VLOOKUP($C$9,#REF!,38,FALSE)="","",VLOOKUP($C$9,#REF!,38,FALSE)),"") | AY31: =IFERROR(IF(VLOOKUP($C$9,#REF!,39,FALSE)="","",VLOOKUP($C$9,#REF!,39,FALSE)),"") | BD31: =IF(OR(AT31="",AY31=""),"",IF(ISERROR(ROUND(AVERAGE(AT31,AY31),0)),"",ROUND(AVERAGE(AT31,AY31),0))) | BI31: =IF(OR(AT31="",AY31="",BD31=""),"",IF(BD31>=75,"PASSED","FAILED"))
A32: =IFERROR(VLOOKUP(I32,#REF!,2,FALSE),"") | I32: =IFERROR(IF(VLOOKUP($C$9,#REF!,41,FALSE)="","",VLOOKUP($C$9,#REF!,41,FALSE)),"") | AT32: =IFERROR(IF(VLOOKUP($C$9,#REF!,42,FALSE)="","",VLOOKUP($C$9,#REF!,42,FALSE)),"") | AY32: =IFERROR(IF(VLOOKUP($C$9,#REF!,43,FALSE)="","",VLOOKUP($C$9,#REF!,43,FALSE)),"") | BD32: =IF(OR(AT32="",AY32=""),"",IF(ISERROR(ROUND(AVERAGE(AT32,AY32),0)),"",ROUND(AVERAGE(AT32,AY32),0))) | BI32: =IF(OR(AT32="",AY32="",BD32=""),"",IF(BD32>=75,"PASSED","FAILED"))
A33: =IFERROR(VLOOKUP(I33,#REF!,2,FALSE),"") | I33: =IFERROR(IF(VLOOKUP($C$9,#REF!,45,FALSE)="","",VLOOKUP($C$9,#REF!,45,FALSE)),"") | AT33: =IFERROR(IF(VLOOKUP($C$9,#REF!,46,FALSE)="","",VLOOKUP($C$9,#REF!,46,FALSE)),"") | AY33: =IFERROR(IF(VLOOKUP($C$9,#REF!,47,FALSE)="","",VLOOKUP($C$9,#REF!,47,FALSE)),"") | BD33: =IF(OR(AT33="",AY33=""),"",IF(ISERROR(ROUND(AVERAGE(AT33,AY33),0)),"",ROUND(AVERAGE(AT33,AY33),0))) | BI33: =IF(OR(AT33="",AY33="",BD33=""),"",IF(BD33>=75,"PASSED","FAILED"))
A34: =IFERROR(VLOOKUP(I34,#REF!,2,FALSE),"") | I34: =IFERROR(IF(VLOOKUP($C$9,#REF!,49,FALSE)="","",VLOOKUP($C$9,#REF!,49,FALSE)),"") | AT34: =IFERROR(IF(VLOOKUP($C$9,#REF!,50,FALSE)="","",VLOOKUP($C$9,#REF!,50,FALSE)),"") | AY34: =IFERROR(IF(VLOOKUP($C$9,#REF!,51,FALSE)="","",VLOOKUP($C$9,#REF!,51,FALSE)),"") | BD34: =IF(OR(AT34="",AY34=""),"",IF(ISERROR(ROUND(AVERAGE(AT34,AY34),0)),"",ROUND(AVERAGE(AT34,AY34),0))) | BI34: =IF(OR(AT34="",AY34="",BD34=""),"",IF(BD34>=75,"PASSED","FAILED"))
A35: =IFERROR(VLOOKUP(I35,#REF!,2,FALSE),"") | I35: =IFERROR(IF(VLOOKUP($C$9,#REF!,53,FALSE)="","",VLOOKUP($C$9,#REF!,53,FALSE)),"") | AT35: =IFERROR(IF(VLOOKUP($C$9,#REF!,54,FALSE)="","",VLOOKUP($C$9,#REF!,54,FALSE)),"") | AY35: =IFERROR(IF(VLOOKUP($C$9,#REF!,55,FALSE)="","",VLOOKUP($C$9,#REF!,55,FALSE)),"") | BD35: =IF(OR(AT35="",AY35=""),"",IF(ISERROR(ROUND(AVERAGE(AT35,AY35),0)),"",ROUND(AVERAGE(AT35,AY35),0))) | BI35: =IF(OR(AT35="",AY35="",BD35=""),"",IF(BD35>=75,"PASSED","FAILED"))
A36: =IFERROR(VLOOKUP(I36,#REF!,2,FALSE),"") | I36: =IFERROR(IF(VLOOKUP($C$9,#REF!,57,FALSE)="","",VLOOKUP($C$9,#REF!,57,FALSE)),"") | AT36: =IFERROR(IF(VLOOKUP($C$9,#REF!,58,FALSE)="","",VLOOKUP($C$9,#REF!,58,FALSE)),"") | AY36: =IFERROR(IF(VLOOKUP($C$9,#REF!,59,FALSE)="","",VLOOKUP($C$9,#REF!,59,FALSE)),"") | BD36: =IF(OR(AT36="",AY36=""),"",IF(ISERROR(ROUND(AVERAGE(AT36,AY36),0)),"",ROUND(AVERAGE(AT36,AY36),0))) | BI36: =IF(OR(AT36="",AY36="",BD36=""),"",IF(BD36>=75,"PASSED","FAILED"))
A37: =IFERROR(VLOOKUP(I37,#REF!,2,FALSE),"") | I37: =IFERROR(IF(VLOOKUP($C$9,#REF!,61,FALSE)="","",VLOOKUP($C$9,#REF!,61,FALSE)),"") | AT37: =IFERROR(IF(VLOOKUP($C$9,#REF!,62,FALSE)="","",VLOOKUP($C$9,#REF!,62,FALSE)),"") | AY37: =IFERROR(IF(VLOOKUP($C$9,#REF!,63,FALSE)="","",VLOOKUP($C$9,#REF!,63,FALSE)),"") | BD37: =IF(OR(AT37="",AY37=""),"",IF(ISERROR(ROUND(AVERAGE(AT37,AY37),0)),"",ROUND(AVERAGE(AT37,AY37),0))) | BI37: =IF(OR(AT37="",AY37="",BD37=""),"",IF(BD37>=75,"PASSED","FAILED"))
A38: =IFERROR(VLOOKUP(I38,#REF!,2,FALSE),"") | I38: =IFERROR(IF(VLOOKUP($C$9,#REF!,65,FALSE)="","",VLOOKUP($C$9,#REF!,65,FALSE)),"") | AT38: =IFERROR(IF(VLOOKUP($C$9,#REF!,66,FALSE)="","",VLOOKUP($C$9,#REF!,66,FALSE)),"") | AY38: =IFERROR(IF(VLOOKUP($C$9,#REF!,67,FALSE)="","",VLOOKUP($C$9,#REF!,67,FALSE)),"") | BD38: =IF(OR(AT38="",AY38=""),"",IF(ISERROR(ROUND(AVERAGE(AT38,AY38),0)),"",ROUND(AVERAGE(AT38,AY38),0))) | BI38: =IF(OR(AT38="",AY38="",BD38=""),"",IF(BD38>=75,"PASSED","FAILED"))
A39: =IFERROR(VLOOKUP(I39,#REF!,2,FALSE),"") | I39: =IFERROR(IF(VLOOKUP($C$9,#REF!,69,FALSE)="","",VLOOKUP($C$9,#REF!,69,FALSE)),"") | AT39: =IFERROR(IF(VLOOKUP($C$9,#REF!,70,FALSE)="","",VLOOKUP($C$9,#REF!,70,FALSE)),"") | AY39: =IFERROR(IF(VLOOKUP($C$9,#REF!,71,FALSE)="","",VLOOKUP($C$9,#REF!,71,FALSE)),"") | BD39: =IF(OR(AT39="",AY39=""),"",IF(ISERROR(ROUND(AVERAGE(AT39,AY39),0)),"",ROUND(AVERAGE(AT39,AY39),0))) | BI39: =IF(OR(AT39="",AY39="",BD39=""),"",IF(BD39>=75,"PASSED","FAILED"))
A40: =IFERROR(VLOOKUP(I40,#REF!,2,FALSE),"") | I40: =IFERROR(IF(VLOOKUP($C$9,#REF!,73,FALSE)="","",VLOOKUP($C$9,#REF!,73,FALSE)),"") | AT40: =IFERROR(IF(VLOOKUP($C$9,#REF!,74,FALSE)="","",VLOOKUP($C$9,#REF!,74,FALSE)),"") | AY40: =IFERROR(IF(VLOOKUP($C$9,#REF!,75,FALSE)="","",VLOOKUP($C$9,#REF!,75,FALSE)),"") | BD40: =IF(OR(AT40="",AY40=""),"",IF(ISERROR(ROUND(AVERAGE(AT40,AY40),0)),"",ROUND(AVERAGE(AT40,AY40),0))) | BI40: =IF(OR(AT40="",AY40="",BD40=""),"",IF(BD40>=75,"PASSED","FAILED"))
A41: =IFERROR(VLOOKUP(I41,#REF!,2,FALSE),"") | I41: =IFERROR(IF(VLOOKUP($C$9,#REF!,77,FALSE)="","",VLOOKUP($C$9,#REF!,77,FALSE)),"") | AT41: =IFERROR(IF(VLOOKUP($C$9,#REF!,78,FALSE)="","",VLOOKUP($C$9,#REF!,78,FALSE)),"") | AY41: =IFERROR(IF(VLOOKUP($C$9,#REF!,79,FALSE)="","",VLOOKUP($C$9,#REF!,79,FALSE)),"") | BD41: =IF(OR(AT41="",AY41=""),"",IF(ISERROR(ROUND(AVERAGE(AT41,AY41),0)),"",ROUND(AVERAGE(AT41,AY41),0))) | BI41: =IF(OR(AT41="",AY41="",BD41=""),"",IF(BD41>=75,"PASSED","FAILED"))
A42: =IFERROR(VLOOKUP(I42,#REF!,2,FALSE),"") | I42: =IFERROR(IF(VLOOKUP($C$9,#REF!,81,FALSE)="","",VLOOKUP($C$9,#REF!,81,FALSE)),"") | AT42: =IFERROR(IF(VLOOKUP($C$9,#REF!,82,FALSE)="","",VLOOKUP($C$9,#REF!,82,FALSE)),"") | AY42: =IFERROR(IF(VLOOKUP($C$9,#REF!,83,FALSE)="","",VLOOKUP($C$9,#REF!,83,FALSE)),"") | BD42: =IF(OR(AT42="",AY42=""),"",IF(ISERROR(ROUND(AVERAGE(AT42,AY42),0)),"",ROUND(AVERAGE(AT42,AY42),0))) | BI42: =IF(OR(AT42="",AY42="",BD42=""),"",IF(BD42>=75,"PASSED","FAILED"))
A43: General Ave. for the Semester: | BD43: =IFERROR(ROUND((SUM(BD31:BD42,BD58:BD61)-SUM(AT58:AT61))/(COUNTA(BD31:BD42)-COUNTBLANK(BD31:BD42)),0),"") | BI43: =IF(BD43="","",IF(BD43>=75,"PASSED","FAILED"))
A45: REMARKS: | E45: =IFERROR(IF(VLOOKUP($C$9,#REF!,86,FALSE)="","",VLOOKUP($C$9,#REF!,86,FALSE)),"")
A47: Prepared by: | V47: Certified True and Correct: | AZ47: Date Checked (MM/DD/YYYY):
Y49: HEIDEE R. PAGULAYAN, Registrar I
A50: Signature of Adviser over Printed Name | Y50: Signature of Authorized Person over Printed Name, Designation
A52: REMEDIAL CLASSES | I52: Conducted from (MM/DD/YYYY): | W52: to (MM/DD/YYYY): | AH52: SCHOOL: | BF52: SCHOOL ID:
A54: Indicate if Subject is CORE, APPLIED, or SPECIALIZED | I54: SUBJECTS | AT54: SEM FINAL GRADE | AY54: REMEDIAL CLASS MARK | BD54: RECOMPUTED FINAL GRADE | BI54: ACTION TAKEN
BD58: =IF(OR(AT58="",AY58=""),"",IF(ISERROR(ROUND(AVERAGE(AT58,AY58),0)),"",ROUND(AVERAGE(AT58,AY58),0))) | BI58: =IF(OR(AT58="",AY58="",BD58=""),"",IF(BD58>=75,"PASSED","FAILED"))
BD59: =IF(OR(AT59="",AY59=""),"",IF(ISERROR(ROUND(AVERAGE(AT59,AY59),0)),"",ROUND(AVERAGE(AT59,AY59),0))) | BI59: =IF(OR(AT59="",AY59="",BD59=""),"",IF(BD59>=75,"PASSED","FAILED"))
BD60: =IF(OR(AT60="",AY60=""),"",IF(ISERROR(ROUND(AVERAGE(AT60,AY60),0)),"",ROUND(AVERAGE(AT60,AY60),0))) | BI60: =IF(OR(AT60="",AY60="",BD60=""),"",IF(BD60>=75,"PASSED","FAILED"))
...

Sheet SF10 BACK
A1: Page 2 | I1: =IF(BP4="","",VLOOKUP(BP5,#REF!,2,FALSE)&", "&VLOOKUP(BP5,#REF!,3,FALSE)&" "&VLOOKUP(BP5,#REF!,4,FALSE)) | BH1: SF10-SHS
A4: SCHOOL: | E4: =IFERROR(IF(VLOOKUP(BP5,#REF!,144,FALSE)="","",VLOOKUP(BP5,#REF!,144,FALSE)),"") | AB4: SCHOOL ID: | AF4: =IFERROR(IF(VLOOKUP(BP5,#REF!,145,FALSE)="","",VLOOKUP(BP5,#REF!,145,FALSE)),"") | AM4: GRADE LEVEL: | AS4: =IFERROR(IF(VLOOKUP(BP5,#REF!,146,FALSE)="","",VLOOKUP(BP5,#REF!,146,FALSE)),"") | AY4: SY: | BA4: =IFERROR(IF(VLOOKUP(BP5,#REF!,147,FALSE)="","",VLOOKUP(BP5,#REF!,147,FALSE)),"") | BH4: SEM: | BK4: =IFERROR(IF(VLOOKUP(BP5,#REF!,150,FALSE)="","",VLOOKUP(BP5,#REF!,150,FALSE)),"")
A5: TRACK/STRAND: | G5: =IFERROR(IF(VLOOKUP(BP5,#REF!,148,FALSE)="","",VLOOKUP(BP5,#REF!,148,FALSE)),"") | AN5: SECTION: | AS5: =IFERROR(IF(VLOOKUP(BP5,#REF!,149,FALSE)="","",VLOOKUP(BP5,#REF!,149,FALSE)),"") | BP5: =IF(BP4="","",VLOOKUP(BP4,#REF!,3,FALSE))
A7: Indicate if Subject is CORE, APPLIED, or SPECIALIZED | I7: SUBJECTS | AT7: Quarter | BD7: SEM FINAL GRADE | BI7: ACTION TAKEN
AT9: =IF(BK4="","",IF(BK4="1ST","1ST",IF(BK4="2ND","3RD"))) | AY9: =IF(BK4="","",IF(BK4="1ST","2ND",IF(BK4="2ND","4TH")))
A11: =IFERROR(VLOOKUP(I11,#REF!,2,FALSE),"") | I11: =IFERROR(IF(VLOOKUP(BP5,#REF!,151,FALSE)="","",VLOOKUP(BP5,#REF!,151,FALSE)),"") | AT11: =IFERROR(IF(VLOOKUP(BP5,#REF!,152,FALSE)="","",VLOOKUP(BP5,#REF!,152,FALSE)),"") | AY11: =IFERROR(IF(VLOOKUP(BP5,#REF!,153,FALSE)="","",VLOOKUP(BP5,#REF!,153,FALSE)),"") | BD11: =IF(OR(AT11="",AY11=""),"",IF(ISERROR(ROUND(AVERAGE(AT11,AY11),0)),"",ROUND(AVERAGE(AT11,AY11),0))) | BI11: =IF(OR(AT11="",AY11="",BD11=""),"",IF(BD11>=75,"PASSED","FAILED"))
A12: =IFERROR(VLOOKUP(I12,#REF!,2,FALSE),"") | I12: =IFERROR(IF(VLOOKUP(BP5,#REF!,155,FALSE)="","",VLOOKUP(BP5,#REF!,155,FALSE)),"") | AT12: =IFERROR(IF(VLOOKUP(BP5,#REF!,156,FALSE)="","",VLOOKUP(BP5,#REF!,156,FALSE)),"") | AY12: =IFERROR(IF(VLOOKUP(BP5,#REF!,157,FALSE)="","",VLOOKUP(BP5,#REF!,157,FALSE)),"") | BD12: =IF(OR(AT12="",AY12=""),"",IF(ISERROR(ROUND(AVERAGE(AT12,AY12),0)),"",ROUND(AVERAGE(AT12,AY12),0))) | BI12: =IF(OR(AT12="",AY12="",BD12=""),"",IF(BD12>=75,"PASSED","FAILED"))
A13: =IFERROR(VLOOKUP(I13,#REF!,2,FALSE),"") | I13: =IFERROR(IF(VLOOKUP(BP5,#REF!,159,FALSE)="","",VLOOKUP(BP5,#REF!,159,FALSE)),"") | AT13: =IFERROR(IF(VLOOKUP(BP5,#REF!,160,FALSE)="","",VLOOKUP(BP5,#REF!,160,FALSE)),"") | AY13: =IFERROR(IF(VLOOKUP(BP5,#REF!,161,FALSE)="","",VLOOKUP(BP5,#REF!,161,FALSE)),"") | BD13: =IF(OR(AT13="",AY13=""),"",IF(ISERROR(ROUND(AVERAGE(AT13,AY13),0)),"",ROUND(AVERAGE(AT13,AY13),0))) | BI13: =IF(OR(AT13="",AY13="",BD13=""),"",IF(BD13>=75,"PASSED","FAILED"))
A14: =IFERROR(VLOOKUP(I14,#REF!,2,FALSE),"") | I14: =IFERROR(IF(VLOOKUP(BP5,#REF!,163,FALSE)="","",VLOOKUP(BP5,#REF!,163,FALSE)),"") | AT14: =IFERROR(IF(VLOOKUP(BP5,#REF!,164,FALSE)="","",VLOOKUP(BP5,#REF!,164,FALSE)),"") | AY14: =IFERROR(IF(VLOOKUP(BP5,#REF!,165,FALSE)="","",VLOOKUP(BP5,#REF!,165,FALSE)),"") | BD14: =IF(OR(AT14="",AY14=""),"",IF(ISERROR(ROUND(AVERAGE(AT14,AY14),0)),"",ROUND(AVERAGE(AT14,AY14),0))) | BI14: =IF(OR(AT14="",AY14="",BD14=""),"",IF(BD14>=75,"PASSED","FAILED"))
A15: =IFERROR(VLOOKUP(I15,#REF!,2,FALSE),"") | I15: =IFERROR(IF(VLOOKUP(BP5,#REF!,167,FALSE)="","",VLOOKUP(BP5,#REF!,167,FALSE)),"") | AT15: =IFERROR(IF(VLOOKUP(BP5,#REF!,168,FALSE)="","",VLOOKUP(BP5,#REF!,168,FALSE)),"") | AY15: =IFERROR(IF(VLOOKUP(BP5,#REF!,169,FALSE)="","",VLOOKUP(BP5,#REF!,169,FALSE)),"") | BD15: =IF(OR(AT15="",AY15=""),"",IF(ISERROR(ROUND(AVERAGE(AT15,AY15),0)),"",ROUND(AVERAGE(AT15,AY15),0))) | BI15: =IF(OR(AT15="",AY15="",BD15=""),"",IF(BD15>=75,"PASSED","FAILED"))
A16: =IFERROR(VLOOKUP(I16,#REF!,2,FALSE),"") | I16: =IFERROR(IF(VLOOKUP(BP5,#REF!,171,FALSE)="","",VLOOKUP(BP5,#REF!,171,FALSE)),"") | AT16: =IFERROR(IF(VLOOKUP(BP5,#REF!,172,FALSE)="","",VLOOKUP(BP5,#REF!,172,FALSE)),"") | AY16: =IFERROR(IF(VLOOKUP(BP5,#REF!,173,FALSE)="","",VLOOKUP(BP5,#REF!,173,FALSE)),"") | BD16: =IF(OR(AT16="",AY16=""),"",IF(ISERROR(ROUND(AVERAGE(AT16,AY16),0)),"",ROUND(AVERAGE(AT16,AY16),0))) | BI16: =IF(OR(AT16="",AY16="",BD16=""),"",IF(BD16>=75,"PASSED","FAILED"))
A17: =IFERROR(VLOOKUP(I17,#REF!,2,FALSE),"") | I17: =IFERROR(IF(VLOOKUP(BP5,#REF!,175,FALSE)="","",VLOOKUP(BP5,#REF!,175,FALSE)),"") | AT17: =IFERROR(IF(VLOOKUP(BP5,#REF!,176,FALSE)="","",VLOOKUP(BP5,#REF!,176,FALSE)),"") | AY17: =IFERROR(IF(VLOOKUP(BP5,#REF!,177,FALSE)="","",VLOOKUP(BP5,#REF!,177,FALSE)),"") | BD17: =IF(OR(AT17="",AY17=""),"",IF(ISERROR(ROUND(AVERAGE(AT17,AY17),0)),"",ROUND(AVERAGE(AT17,AY17),0))) | BI17: =IF(OR(AT17="",AY17="",BD17=""),"",IF(BD17>=75,"PASSED","FAILED"))
A18: =IFERROR(VLOOKUP(I18,#REF!,2,FALSE),"") | I18: =IFERROR(IF(VLOOKUP(BP5,#REF!,179,FALSE)="","",VLOOKUP(BP5,#REF!,179,FALSE)),"") | AT18: =IFERROR(IF(VLOOKUP(BP5,#REF!,180,FALSE)="","",VLOOKUP(BP5,#REF!,180,FALSE)),"") | AY18: =IFERROR(IF(VLOOKUP(BP5,#REF!,181,FALSE)="","",VLOOKUP(BP5,#REF!,181,FALSE)),"") | BD18: =IF(OR(AT18="",AY18=""),"",IF(ISERROR(ROUND(AVERAGE(AT18,AY18),0)),"",ROUND(AVERAGE(AT18,AY18),0))) | BI18: =IF(OR(AT18="",AY18="",BD18=""),"",IF(BD18>=75,"PASSED","FAILED"))
A19: =IFERROR(VLOOKUP(I19,#REF!,2,FALSE),"") | I19: =IFERROR(IF(VLOOKUP(BP5,#REF!,183,FALSE)="","",VLOOKUP(BP5,#REF!,183,FALSE)),"") | AT19: =IFERROR(IF(VLOOKUP(BP5,#REF!,184,FALSE)="","",VLOOKUP(BP5,#REF!,184,FALSE)),"") | AY19: =IFERROR(IF(VLOOKUP(BP5,#REF!,185,FALSE)="","",VLOOKUP(BP5,#REF!,185,FALSE)),"") | BD19: =IF(OR(AT19="",AY19=""),"",IF(ISERROR(ROUND(AVERAGE(AT19,AY19),0)),"",ROUND(AVERAGE(AT19,AY19),0))) | BI19: =IF(OR(AT19="",AY19="",BD19=""),"",IF(BD19>=75,"PASSED","FAILED"))
A20: =IFERROR(VLOOKUP(I20,#REF!,2,FALSE),"") | I20: =IFERROR(IF(VLOOKUP(BP5,#REF!,187,FALSE)="","",VLOOKUP(BP5,#REF!,187,FALSE)),"") | AT20: =IFERROR(IF(VLOOKUP(BP5,#REF!,188,FALSE)="","",VLOOKUP(BP5,#REF!,188,FALSE)),"") | AY20: =IFERROR(IF(VLOOKUP(BP5,#REF!,189,FALSE)="","",VLOOKUP(BP5,#REF!,189,FALSE)),"") | BD20: =IF(OR(AT20="",AY20=""),"",IF(ISERROR(ROUND(AVERAGE(AT20,AY20),0)),"",ROUND(AVERAGE(AT20,AY20),0))) | BI20: =IF(OR(AT20="",AY20="",BD20=""),"",IF(BD20>=75,"PASSED","FAILED"))
A21: =IFERROR(VLOOKUP(I21,#REF!,2,FALSE),"") | I21: =IFERROR(IF(VLOOKUP(BP5,#REF!,191,FALSE)="","",VLOOKUP(BP5,#REF!,191,FALSE)),"") | AT21: =IFERROR(IF(VLOOKUP(BP5,#REF!,192,FALSE)="","",VLOOKUP(BP5,#REF!,192,FALSE)),"") | AY21: =IFERROR(IF(VLOOKUP(BP5,#REF!,193,FALSE)="","",VLOOKUP(BP5,#REF!,193,FALSE)),"") | BD21: =IF(OR(AT21="",AY21=""),"",IF(ISERROR(ROUND(AVERAGE(AT21,AY21),0)),"",ROUND(AVERAGE(AT21,AY21),0))) | BI21: =IF(OR(AT21="",AY21="",BD21=""),"",IF(BD21>=75,"PASSED","FAILED"))
A22: =IFERROR(VLOOKUP(I22,#REF!,2,FALSE),"") | I22: =IFERROR(IF(VLOOKUP(BP5,#REF!,195,FALSE)="","",VLOOKUP(BP5,#REF!,195,FALSE)),"") | AT22: =IFERROR(IF(VLOOKUP(BP5,#REF!,196,FALSE)="","",VLOOKUP(BP5,#REF!,196,FALSE)),"") | AY22: =IFERROR(IF(VLOOKUP(BP5,#REF!,197,FALSE)="","",VLOOKUP(BP5,#REF!,197,FALSE)),"") | BD22: =IF(OR(AT22="",AY22=""),"",IF(ISERROR(ROUND(AVERAGE(AT22,AY22),0)),"",ROUND(AVERAGE(AT22,AY22),0))) | BI22: =IF(OR(AT22="",AY22="",BD22=""),"",IF(BD22>=75,"PASSED","FAILED"))
A23: General Ave. for the Semester: | BD23: =IFERROR(ROUND((SUM(BD11:BD22,BD38:BD41)-SUM(AT38:AT41))/(COUNTA(BD11:BD22)-COUNTBLANK(BD11:BD22)),0),"") | BI23: =IF(BD23="","",IF(BD23>=75,"PASSED","FAILED"))
A25: REMARKS: | F25: =IFERROR(IF(VLOOKUP(BP5,#REF!,200,FALSE)="","",VLOOKUP(BP5,#REF!,200,FALSE)),"")
A27: Prepared by: | V27: Certified True and Correct: | AZ27: Date Checked (MM/DD/YYYY):
A29: =IFERROR(IF(VLOOKUP(BP5,#REF!,261,FALSE)="","",VLOOKUP(BP5,#REF!,261,FALSE)),"") | Y29: =IF(A29="","","MARILOU M. ALBAY, OIC - Registrar")
A30: Signature of Adviser over Printed Name | Y30: Signature of Authorized Person over Printed Name, Designation
A32: REMEDIAL CLASSES | G32: Conducted from (MM/DD/YYYY): | W32: to (MM/DD/YYYY): | AH32: SCHOOL: | BF32: SCHOOL ID:
A34: Indicate if Subject is CORE, APPLIED, or SPECIALIZED | I34: SUBJECTS | AT34: SEM FINAL GRADE | AY34: REMEDIAL CLASS MARK | BD34: RECOMPUTED FINAL GRADE | BI34: ACTION TAKEN
BD38: =IF(OR(AT38="",AY38=""),"",IF(ISERROR(ROUND(AVERAGE(AT38,AY38),0)),"",ROUND(AVERAGE(AT38,AY38),0))) | BI38: =IF(OR(AT38="",AY38="",BD38=""),"",IF(BD38>=75,"PASSED","FAILED"))
BD39: =IF(OR(AT39="",AY39=""),"",IF(ISERROR(ROUND(AVERAGE(AT39,AY39),0)),"",ROUND(AVERAGE(AT39,AY39),0))) | BI39: =IF(OR(AT39="",AY39="",BD39=""),"",IF(BD39>=75,"PASSED","FAILED"))
BD40: =IF(OR(AT40="",AY40=""),"",IF(ISERROR(ROUND(AVERAGE(AT40,AY40),0)),"",ROUND(AVERAGE(AT40,AY40),0))) | BI40: =IF(OR(AT40="",AY40="",BD40=""),"",IF(BD40>=75,"PASSED","FAILED"))
BD41: =IF(OR(AT41="",AY41=""),"",IF(ISERROR(ROUND(AVERAGE(AT41,AY41),0)),"",ROUND(AVERAGE(AT41,AY41),0))) | BI41: =IF(OR(AT41="",AY41="",BD41=""),"",IF(BD41>=75,"PASSED","FAILED"))
A43: Name of Teacher/Adviser: | AT43: Signature:
A46: SCHOOL: | E46: =IFERROR(IF(VLOOKUP(BP5,#REF!,201,FALSE)="","",VLOOKUP(BP5,#REF!,201,FALSE)),"") | AB46: SCHOOL ID: | AF46: =IFERROR(IF(VLOOKUP(BP5,#REF!,202,FALSE)="","",VLOOKUP(BP5,#REF!,202,FALSE)),"") | AM46: GRADE LEVEL: | AS46: =IFERROR(IF(VLOOKUP(BP5,#REF!,203,FALSE)="","",VLOOKUP(BP5,#REF!,203,FALSE)),"") | AY46: SY: | BA46: =IFERROR(IF(VLOOKUP(BP5,#REF!,204,FALSE)="","",VLOOKUP(BP5,#REF!,204,FALSE)),"") | BH46: SEM: | BK46: =IFERROR(IF(VLOOKUP(BP5,#REF!,207,FALSE)="","",VLOOKUP(BP5,#REF!,207,FALSE)),"")
A48: TRACK/STRAND: | G48: =IFERROR(IF(VLOOKUP(BP5,#REF!,205,FALSE)="","",VLOOKUP(BP5,#REF!,205,FALSE)),"") | AN48: SECTION: | AS48: =IFERROR(IF(VLOOKUP(BP5,#REF!,206,FALSE)="","",VLOOKUP(BP5,#REF!,206,FALSE)),"")
A50: Indicate if Subject is CORE, APPLIED, or SPECIALIZED | I50: SUBJECTS | AT50: Quarter | BD50: SEM FINAL GRADE | BI50: ACTION TAKEN
AT52: =IF(BK46="","",IF(BK46="1ST","1ST",IF(BK46="2ND","3RD"))) | AY52: =IF(BK46="","",IF(BK46="1ST","2ND",IF(BK46="2ND","4TH")))
A54: =IFERROR(VLOOKUP(I54,#REF!,2,FALSE),"") | I54: =IFERROR(IF(VLOOKUP(BP5,#REF!,208,FALSE)="","",VLOOKUP(BP5,#REF!,208,FALSE)),"") | AT54: =IFERROR(IF(VLOOKUP(BP5,#REF!,209,FALSE)="","",VLOOKUP(BP5,#REF!,209,FALSE)),"") | AY54: =IFERROR(IF(VLOOKUP(BP5,#REF!,210,FALSE)="","",VLOOKUP(BP5,#REF!,210,FALSE)),"") | BD54: =IF(OR(AT54="",AY54=""),"",IF(ISERROR(ROUND(AVERAGE(AT54,AY54),0)),"",ROUND(AVERAGE(AT54,AY54),0))) | BI54: =IF(OR(AT54="",AY54="",BD54=""),"",IF(BD54>=75,"PASSED","FAILED"))
A55: =IFERROR(VLOOKUP(I55,#REF!,2,FALSE),"") | I55: =IFERROR(IF(VLOOKUP(BP5,#REF!,212,FALSE)="","",VLOOKUP(BP5,#REF!,212,FALSE)),"") | AT55: =IFERROR(IF(VLOOKUP(BP5,#REF!,213,FALSE)="","",VLOOKUP(BP5,#REF!,213,FALSE)),"") | AY55: =IFERROR(IF(VLOOKUP(BP5,#REF!,214,FALSE)="","",VLOOKUP(BP5,#REF!,214,FALSE)),"") | BD55: =IF(OR(AT55="",AY55=""),"",IF(ISERROR(ROUND(AVERAGE(AT55,AY55),0)),"",ROUND(AVERAGE(AT55,AY55),0))) | BI55: =IF(OR(AT55="",AY55="",BD55=""),"",IF(BD55>=75,"PASSED","FAILED"))
A56: =IFERROR(VLOOKUP(I56,#REF!,2,FALSE),"") | I56: =IFERROR(IF(VLOOKUP(BP5,#REF!,216,FALSE)="","",VLOOKUP(BP5,#REF!,216,FALSE)),"") | AT56: =IFERROR(IF(VLOOKUP(BP5,#REF!,217,FALSE)="","",VLOOKUP(BP5,#REF!,217,FALSE)),"") | AY56: =IFERROR(IF(VLOOKUP(BP5,#REF!,218,FALSE)="","",VLOOKUP(BP5,#REF!,218,FALSE)),"") | BD56: =IF(OR(AT56="",AY56=""),"",IF(ISERROR(ROUND(AVERAGE(AT56,AY56),0)),"",ROUND(AVERAGE(AT56,AY56),0))) | BI56: =IF(OR(AT56="",AY56="",BD56=""),"",IF(BD56>=75,"PASSED","FAILED"))
A57: =IFERROR(VLOOKUP(I57,#REF!,2,FALSE),"") | I57: =IFERROR(IF(VLOOKUP(BP5,#REF!,220,FALSE)="","",VLOOKUP(BP5,#REF!,220,FALSE)),"") | AT57: =IFERROR(IF(VLOOKUP(BP5,#REF!,221,FALSE)="","",VLOOKUP(BP5,#REF!,221,FALSE)),"") | AY57: =IFERROR(IF(VLOOKUP(BP5,#REF!,222,FALSE)="","",VLOOKUP(BP5,#REF!,222,FALSE)),"") | BD57: =IF(OR(AT57="",AY57=""),"",IF(ISERROR(ROUND(AVERAGE(AT57,AY57),0)),"",ROUND(AVERAGE(AT57,AY57),0))) | BI57: =IF(OR(AT57="",AY57="",BD57=""),"",IF(BD57>=75,"PASSED","FAILED"))
A58: =IFERROR(VLOOKUP(I58,#REF!,2,FALSE),"") | I58: =IFERROR(IF(VLOOKUP(BP5,#REF!,224,FALSE)="","",VLOOKUP(BP5,#REF!,224,FALSE)),"") | AT58: =IFERROR(IF(VLOOKUP(BP5,#REF!,225,FALSE)="","",VLOOKUP(BP5,#REF!,225,FALSE)),"") | AY58: =IFERROR(IF(VLOOKUP(BP5,#REF!,226,FALSE)="","",VLOOKUP(BP5,#REF!,226,FALSE)),"") | BD58: =IF(OR(AT58="",AY58=""),"",IF(ISERROR(ROUND(AVERAGE(AT58,AY58),0)),"",ROUND(AVERAGE(AT58,AY58),0))) | BI58: =IF(OR(AT58="",AY58="",BD58=""),"",IF(BD58>=75,"PASSED","FAILED"))
A59: =IFERROR(VLOOKUP(I59,#REF!,2,FALSE),"") | I59: =IFERROR(IF(VLOOKUP(BP5,#REF!,228,FALSE)="","",VLOOKUP(BP5,#REF!,228,FALSE)),"") | AT59: =IFERROR(IF(VLOOKUP(BP5,#REF!,229,FALSE)="","",VLOOKUP(BP5,#REF!,229,FALSE)),"") | AY59: =IFERROR(IF(VLOOKUP(BP5,#REF!,230,FALSE)="","",VLOOKUP(BP5,#REF!,230,FALSE)),"") | BD59: =IF(OR(AT59="",AY59=""),"",IF(ISERROR(ROUND(AVERAGE(AT59,AY59),0)),"",ROUND(AVERAGE(AT59,AY59),0))) | BI59: =IF(OR(AT59="",AY59="",BD59=""),"",IF(BD59>=75,"PASSED","FAILED"))
A60: =IFERROR(VLOOKUP(I60,#REF!,2,FALSE),"") | I60: =IFERROR(IF(VLOOKUP(BP5,#REF!,232,FALSE)="","",VLOOKUP(BP5,#REF!,232,FALSE)),"") | AT60: =IFERROR(IF(VLOOKUP(BP5,#REF!,233,FALSE)="","",VLOOKUP(BP5,#REF!,233,FALSE)),"") | AY60: =IFERROR(IF(VLOOKUP(BP5,#REF!,234,FALSE)="","",VLOOKUP(BP5,#REF!,234,FALSE)),"") | BD60: =IF(OR(AT60="",AY60=""),"",IF(ISERROR(ROUND(AVERAGE(AT60,AY60),0)),"",ROUND(AVERAGE(AT60,AY60),0))) | BI60: =IF(OR(AT60="",AY60="",BD60=""),"",IF(BD60>=75,"PASSED","FAILED"))
...

Sheet Helper(IMPORTANT!)
B1: Helper Columns
B2: yongbarba@gmail.com
B3: Subjects | C3: Core | D3: Applied | E3: Specialized | F3: Other Subjects
A4: 1 | B4: =IF('SF10 FRONT'!A31="Core","Core",IF('SF10 FRONT'!A31="Applied","Applied",IF('SF10 FRONT'!A31="Specialized","Specialized",IF('SF10 FRONT'!A31="Other_Subjects","Other_Subjects")))) -> FALSE | C4: 21st Century Literature from the Philippines and the World | D4: Empowerment Technologies | E4: =IF(#REF!="","",#REF!) -> #REF! | F4: =IF(#REF!="","",#REF!) -> #REF!
B5: =IF('SF10 FRONT'!A32="Core","Core",IF('SF10 FRONT'!A32="Applied","Applied",IF('SF10 FRONT'!A32="Specialized","Specialized",IF('SF10 FRONT'!A32="Other_Subjects","Other_Subjects")))) -> FALSE | C5: Contemporary Philippine Arts from the Regions | D5: English for Academic and Professional Purposes | E5: =IF(#REF!="","",#REF!) -> #REF! | F5: =IF(#REF!="","",#REF!) -> #REF!
B6: =IF('SF10 FRONT'!A33="Core","Core",IF('SF10 FRONT'!A33="Applied","Applied",IF('SF10 FRONT'!A33="Specialized","Specialized",IF('SF10 FRONT'!A33="Other_Subjects","Other_Subjects")))) -> FALSE | C6: Disaster Readiness and Risk Reduction | D6: Entrepreneurship | E6: =IF(#REF!="","",#REF!) -> #REF! | F6: =IF(#REF!="","",#REF!) -> #REF! | J6: PASSED | M6: Physical Education and Health
B7: =IF('SF10 FRONT'!A34="Core","Core",IF('SF10 FRONT'!A34="Applied","Applied",IF('SF10 FRONT'!A34="Specialized","Specialized",IF('SF10 FRONT'!A34="Other_Subjects","Other_Subjects")))) -> FALSE | C7: Earth and Life Science* | D7: Filipino sa Piling Larang | E7: =IF(#REF!="","",#REF!) -> #REF! | I7: 1 | J7: ='SF10 FRONT'!I31 | K7: ='SF10 FRONT'!BI31 | L7: =IF(K7="PASSED","∕","") | M7: {=IFERROR(INDEX('SF10 FRONT'!I31:BI42,MATCH(1,('SF10 FRONT'!I31:I42=$M$6)*('SF10 FRONT'!BI31:BI42=$J$6),0),53),"")}
B8: =IF('SF10 FRONT'!A35="Core","Core",IF('SF10 FRONT'!A35="Applied","Applied",IF('SF10 FRONT'!A35="Specialized","Specialized",IF('SF10 FRONT'!A35="Other_Subjects","Other_Subjects")))) -> FALSE | C8: Earth Science | D8: Inquiries, Investigations and Immersion | E8: =IF(#REF!="","",#REF!) -> #REF! | J8: ='SF10 FRONT'!I32 | K8: ='SF10 FRONT'!BI32 | L8: =IF(K8="PASSED","∕","") | M8: {=IFERROR(INDEX('SF10 FRONT'!I58:BI61,MATCH(1,('SF10 FRONT'!I58:I61=$M$6)*('SF10 FRONT'!BI58:BI61=$J$6),0),53),"")}
B9: =IF('SF10 FRONT'!A36="Core","Core",IF('SF10 FRONT'!A36="Applied","Applied",IF('SF10 FRONT'!A36="Specialized","Specialized",IF('SF10 FRONT'!A36="Other_Subjects","Other_Subjects")))) -> FALSE | C9: General Mathematics | D9: Practical Research 1 | E9: =IF(#REF!="","",#REF!) -> #REF! | J9: ='SF10 FRONT'!I33 | K9: ='SF10 FRONT'!BI33 | L9: =IF(K9="PASSED","∕","") | M9: {=IFERROR(INDEX('SF10 FRONT'!I74:BI85,MATCH(1,('SF10 FRONT'!I74:I85=$M$6)*('SF10 FRONT'!BI74:BI85=$J$6),0),53),"")}
B10: =IF('SF10 FRONT'!A37="Core","Core",IF('SF10 FRONT'!A37="Applied","Applied",IF('SF10 FRONT'!A37="Specialized","Specialized",IF('SF10 FRONT'!A37="Other_Subjects","Other_Subjects")))) -> FALSE | C10: Introduction to the Philosophy of the Human Person/Pambungad sa Pilosopiya ng Tao | D10: Practical Research 2 | E10: =IF(#REF!="","",#REF!) -> #REF! | J10: ='SF10 FRONT'!I34 | K10: ='SF10 FRONT'!BI34 | L10: =IF(K10="PASSED","∕","") | M10: {=IFERROR(INDEX('SF10 FRONT'!I101:BI104,MATCH(1,('SF10 FRONT'!I101:I104=$M$6)*('SF10 FRONT'!BI101:BI104=$J$6),0),53),"")}
B11: =IF('SF10 FRONT'!A38="Core","Core",IF('SF10 FRONT'!A38="Applied","Applied",IF('SF10 FRONT'!A38="Specialized","Specialized",IF('SF10 FRONT'!A38="Other_Subjects","Other_Subjects")))) -> FALSE | C11: Komunikasyon at Pananaliksik sa Wika at Kulturang Pilipino | E11: =IF(#REF!="","",#REF!) -> #REF! | J11: ='SF10 FRONT'!I35 | K11: ='SF10 FRONT'!BI35 | L11: =IF(K11="PASSED","∕","") | M11: {=IFERROR(INDEX('SF10 BACK'!I11:BI22,MATCH(1,('SF10 BACK'!I11:I22=$M$6)*('SF10 BACK'!BI11:BI22=$J$6),0),53),"")}
B12: =IF('SF10 FRONT'!A39="Core","Core",IF('SF10 FRONT'!A39="Applied","Applied",IF('SF10 FRONT'!A39="Specialized","Specialized",IF('SF10 FRONT'!A39="Other_Subjects","Other_Subjects")))) -> FALSE | C12: Media and Information Literacy | E12: =IF(#REF!="","",#REF!) -> #REF! | J12: ='SF10 FRONT'!I36 | K12: ='SF10 FRONT'!BI36 | L12: =IF(K12="PASSED","∕","") | M12: {=IFERROR(INDEX('SF10 BACK'!I38:BI41,MATCH(1,('SF10 BACK'!I38:I41=$M$6)*('SF10 BACK'!BI38:BI41=$J$6),0),53),"")}
B13: =IF('SF10 FRONT'!A40="Core","Core",IF('SF10 FRONT'!A40="Applied","Applied",IF('SF10 FRONT'!A40="Specialized","Specialized",IF('SF10 FRONT'!A40="Other_Subjects","Other_Subjects")))) -> FALSE | C13: Oral Communication | J13: ='SF10 FRONT'!I37 | K13: ='SF10 FRONT'!BI37 | L13: =IF(K13="PASSED","∕","") | M13: {=IFERROR(INDEX('SF10 BACK'!I54:BI65,MATCH(1,('SF10 BACK'!I54:I65=$M$6)*('SF10 BACK'!BI54:BI65=$J$6),0),53),"")}
B14: =IF('SF10 FRONT'!A41="Core","Core",IF('SF10 FRONT'!A41="Applied","Applied",IF('SF10 FRONT'!A41="Specialized","Specialized",IF('SF10 FRONT'!A41="Other_Subjects","Other_Subjects")))) -> FALSE | C14: Pagbasa at Pagsusuri ng Iba't Ibang Teksto Tungo sa Pananaliksik | J14: ='SF10 FRONT'!I38 | K14: ='SF10 FRONT'!BI38 | L14: =IF(K14="PASSED","∕","") | M14: {=IFERROR(INDEX('SF10 BACK'!I81:BI84,MATCH(1,('SF10 BACK'!I81:I84=$M$6)*('SF10 BACK'!BI81:BI84=$J$6),0),53),"")}
B15: =IF('SF10 FRONT'!A42="Core","Core",IF('SF10 FRONT'!A42="Applied","Applied",IF('SF10 FRONT'!A42="Specialized","Specialized",IF('SF10 FRONT'!A42="Other_Subjects","Other_Subjects")))) -> FALSE | C15: Personal Development/Pansariling Kaunlaran | J15: ='SF10 FRONT'!I39 | K15: ='SF10 FRONT'!BI39 | L15: =IF(K15="PASSED","∕","")
A16: 2 | B16: =IF('SF10 FRONT'!A58="Core","Core",IF('SF10 FRONT'!A58="Applied","Applied",IF('SF10 FRONT'!A58="Specialized","Specialized",IF('SF10 FRONT'!A58="Other_Subjects","Other_Subjects")))) -> FALSE | C16: Physical Education and Health | J16: ='SF10 FRONT'!I40 | K16: ='SF10 FRONT'!BI40 | L16: =IF(K16="PASSED","∕","")
B17: =IF('SF10 FRONT'!A59="Core","Core",IF('SF10 FRONT'!A59="Applied","Applied",IF('SF10 FRONT'!A59="Specialized","Specialized",IF('SF10 FRONT'!A59="Other_Subjects","Other_Subjects")))) -> FALSE | C17: Physical Science* | J17: ='SF10 FRONT'!I41 | K17: ='SF10 FRONT'!BI41 | L17: =IF(K17="PASSED","∕","")
B18: =IF('SF10 FRONT'!#REF!="Core","Core",IF('SF10 FRONT'!#REF!="Applied","Applied",IF('SF10 FRONT'!#REF!="Specialized","Specialized",IF('SF10 FRONT'!#REF!="Other_Subjects","Other_Subjects")))) -> #REF! | C18: Reading and Writing | J18: ='SF10 FRONT'!I42 | K18: ='SF10 FRONT'!BI42 | L18: =IF(K18="PASSED","∕","")
B19: =IF('SF10 FRONT'!#REF!="Core","Core",IF('SF10 FRONT'!#REF!="Applied","Applied",IF('SF10 FRONT'!#REF!="Specialized","Specialized",IF('SF10 FRONT'!#REF!="Other_Subjects","Other_Subjects")))) -> #REF! | C19: Statistics and Probability | I19: 2 | J19: ='SF10 FRONT'!I58 -> 0 | K19: ='SF10 FRONT'!BI58 | L19: =IF(K19="PASSED","∕","")
B20: =IF('SF10 FRONT'!#REF!="Core","Core",IF('SF10 FRONT'!#REF!="Applied","Applied",IF('SF10 FRONT'!#REF!="Specialized","Specialized",IF('SF10 FRONT'!#REF!="Other_Subjects","Other_Subjects")))) -> #REF! | C20: Understanding Culture, Society and Politics | J20: ='SF10 FRONT'!I59 -> 0 | K20: ='SF10 FRONT'!BI59 | L20: =IF(K20="PASSED","∕","")
B21: =IF('SF10 FRONT'!#REF!="Core","Core",IF('SF10 FRONT'!#REF!="Applied","Applied",IF('SF10 FRONT'!#REF!="Specialized","Specialized",IF('SF10 FRONT'!#REF!="Other_Subjects","Other_Subjects")))) -> #REF! | C21: =IF(#REF!="","",#REF!) -> #REF! | J21: ='SF10 FRONT'!#REF! -> #REF! | K21: ='SF10 FRONT'!#REF! -> #REF! | L21: =IF(K21="PASSED","∕","") -> #REF!
B22: =IF('SF10 FRONT'!A60="Core","Core",IF('SF10 FRONT'!A60="Applied","Applied",IF('SF10 FRONT'!A60="Specialized","Specialized",IF('SF10 FRONT'!A60="Other_Subjects","Other_Subjects")))) -> FALSE | C22: =IF(#REF!="","",#REF!) -> #REF! | J22: ='SF10 FRONT'!#REF! -> #REF! | K22: ='SF10 FRONT'!#REF! -> #REF! | L22: =IF(K22="PASSED","∕","") -> #REF!
B23: =IF('SF10 FRONT'!A61="Core","Core",IF('SF10 FRONT'!A61="Applied","Applied",IF('SF10 FRONT'!A61="Specialized","Specialized",IF('SF10 FRONT'!A61="Other_Subjects","Other_Subjects")))) -> FALSE | J23: ='SF10 FRONT'!#REF! -> #REF! | K23: ='SF10 FRONT'!#REF! -> #REF! | L23: =IF(K23="PASSED","∕","") -> #REF!
B24: =IF('SF10 FRONT'!A62="Core","Core",IF('SF10 FRONT'!A62="Applied","Applied",IF('SF10 FRONT'!A62="Specialized","Specialized",IF('SF10 FRONT'!A62="Other_Subjects","Other_Subjects")))) -> FALSE | J24: ='SF10 FRONT'!#REF! -> #REF! | K24: ='SF10 FRONT'!#REF! -> #REF! | L24: =IF(K24="PASSED","∕","") -> #REF!
B25: =IF('SF10 FRONT'!A63="Core","Core",IF('SF10 FRONT'!A63="Applied","Applied",IF('SF10 FRONT'!A63="Specialized","Specialized",IF('SF10 FRONT'!A63="Other_Subjects","Other_Subjects")))) -> FALSE | J25: ='SF10 FRONT'!I60 -> 0 | K25: ='SF10 FRONT'!BI60 | L25: =IF(K25="PASSED","∕","")
B26: =IF('SF10 FRONT'!A64="Core","Core",IF('SF10 FRONT'!A64="Applied","Applied",IF('SF10 FRONT'!A64="Specialized","Specialized",IF('SF10 FRONT'!A64="Other_Subjects","Other_Subjects")))) -> FALSE | J26: ='SF10 FRONT'!I61 -> 0 | K26: ='SF10 FRONT'!BI61 | L26: =IF(K26="PASSED","∕","")
B27: =IF('SF10 FRONT'!A65="Core","Core",IF('SF10 FRONT'!A65="Applied","Applied",IF('SF10 FRONT'!A65="Specialized","Specialized",IF('SF10 FRONT'!A65="Other_Subjects","Other_Subjects")))) -> FALSE | I27: 3 | J27: ='SF10 FRONT'!I74 | K27: ='SF10 FRONT'!BI74 | L27: =IF(K27="PASSED","∕","")
A28: 3 | B28: =IF('SF10 FRONT'!A74="Core","Core",IF('SF10 FRONT'!A74="Applied","Applied",IF('SF10 FRONT'!A74="Specialized","Specialized",IF('SF10 FRONT'!A74="Other_Subjects","Other_Subjects")))) -> FALSE | J28: ='SF10 FRONT'!I75 | K28: ='SF10 FRONT'!BI75 | L28: =IF(K28="PASSED","∕","")
B29: =IF('SF10 FRONT'!A75="Core","Core",IF('SF10 FRONT'!A75="Applied","Applied",IF('SF10 FRONT'!A75="Specialized","Specialized",IF('SF10 FRONT'!A75="Other_Subjects","Other_Subjects")))) -> FALSE | J29: ='SF10 FRONT'!I76 | K29: ='SF10 FRONT'!BI76 | L29: =IF(K29="PASSED","∕","")
B30: =IF('SF10 FRONT'!A76="Core","Core",IF('SF10 FRONT'!A76="Applied","Applied",IF('SF10 FRONT'!A76="Specialized","Specialized",IF('SF10 FRONT'!A76="Other_Subjects","Other_Subjects")))) -> FALSE | J30: ='SF10 FRONT'!I77 | K30: ='SF10 FRONT'!BI77 | L30: =IF(K30="PASSED","∕","")
B31: =IF('SF10 FRONT'!A77="Core","Core",IF('SF10 FRONT'!A77="Applied","Applied",IF('SF10 FRONT'!A77="Specialized","Specialized",IF('SF10 FRONT'!A77="Other_Subjects","Other_Subjects")))) -> FALSE | J31: ='SF10 FRONT'!I78 | K31: ='SF10 FRONT'!BI78 | L31: =IF(K31="PASSED","∕","")
B32: =IF('SF10 FRONT'!A78="Core","Core",IF('SF10 FRONT'!A78="Applied","Applied",IF('SF10 FRONT'!A78="Specialized","Specialized",IF('SF10 FRONT'!A78="Other_Subjects","Other_Subjects")))) -> FALSE | J32: ='SF10 FRONT'!I79 | K32: ='SF10 FRONT'!BI79 | L32: =IF(K32="PASSED","∕","")
B33: =IF('SF10 FRONT'!A79="Core","Core",IF('SF10 FRONT'!A79="Applied","Applied",IF('SF10 FRONT'!A79="Specialized","Specialized",IF('SF10 FRONT'!A79="Other_Subjects","Other_Subjects")))) -> FALSE | J33: ='SF10 FRONT'!I80 | K33: ='SF10 FRONT'!BI80 | L33: =IF(K33="PASSED","∕","")
B34: =IF('SF10 FRONT'!A80="Core","Core",IF('SF10 FRONT'!A80="Applied","Applied",IF('SF10 FRONT'!A80="Specialized","Specialized",IF('SF10 FRONT'!A80="Other_Subjects","Other_Subjects")))) -> FALSE | J34: ='SF10 FRONT'!I81 | K34: ='SF10 FRONT'!BI81 | L34: =IF(K34="PASSED","∕","")
B35: =IF('SF10 FRONT'!A81="Core","Core",IF('SF10 FRONT'!A81="Applied","Applied",IF('SF10 FRONT'!A81="Specialized","Specialized",IF('SF10 FRONT'!A81="Other_Subjects","Other_Subjects")))) -> FALSE | J35: ='SF10 FRONT'!I82 | K35: ='SF10 FRONT'!BI82 | L35: =IF(K35="PASSED","∕","")
B36: =IF('SF10 FRONT'!A82="Core","Core",IF('SF10 FRONT'!A82="Applied","Applied",IF('SF10 FRONT'!A82="Specialized","Specialized",IF('SF10 FRONT'!A82="Other_Subjects","Other_Subjects")))) -> FALSE | J36: ='SF10 FRONT'!I83 | K36: ='SF10 FRONT'!BI83 | L36: =IF(K36="PASSED","∕","")
B37: =IF('SF10 FRONT'!A83="Core","Core",IF('SF10 FRONT'!A83="Applied","Applied",IF('SF10 FRONT'!A83="Specialized","Specialized",IF('SF10 FRONT'!A83="Other_Subjects","Other_Subjects")))) -> FALSE | J37: ='SF10 FRONT'!I84 | K37: ='SF10 FRONT'!BI84 | L37: =IF(K37="PASSED","∕","")
B38: =IF('SF10 FRONT'!A84="Core","Core",IF('SF10 FRONT'!A84="Applied","Applied",IF('SF10 FRONT'!A84="Specialized","Specialized",IF('SF10 FRONT'!A84="Other_Subjects","Other_Subjects")))) -> FALSE | J38: ='SF10 FRONT'!I85 | K38: ='SF10 FRONT'!BI85 | L38: =IF(K38="PASSED","∕","")
B39: =IF('SF10 FRONT'!A85="Core","Core",IF('SF10 FRONT'!A85="Applied","Applied",IF('SF10 FRONT'!A85="Specialized","Specialized",IF('SF10 FRONT'!A85="Other_Subjects","Other_Subjects")))) -> FALSE | I39: 4 | J39: ='SF10 FRONT'!I101 -> 0 | K39: ='SF10 FRONT'!BI101 | L39: =IF(K39="PASSED","∕","")
A40: 4 | B40: =IF('SF10 FRONT'!A101="Core","Core",IF('SF10 FRONT'!A101="Applied","Applied",IF('SF10 FRONT'!A101="Specialized","Specialized",IF('SF10 FRONT'!A101="Other_Subjects","Other_Subjects")))) -> FALSE | J40: ='SF10 FRONT'!I102 -> 0 | K40: ='SF10 FRONT'!BI102 | L40: =IF(K40="PASSED","∕","")
...
